<?xml version="1.0" ?>
<sdf version="1.5">
	<model name="gripper_four_finger">
		<link name="base">
			<pose>0.0 0.0 0.0 1.5707963705062866 -0.0 0.0</pose>
			<inertial>
				<mass>1.0</mass>
				<pose>0 0 0 0 0 0</pose>
				<inertia>
					<ixx>1.0</ixx>
					<ixy>0.0</ixy>
					<ixz>0.0</ixz>
					<iyy>1.0</iyy>
					<iyz>0.0</iyz>
					<izz>1.0</izz>
				</inertia>
			</inertial>
			<collision name="COL__SCHUNK-5515455_G0_COL">
				<pose>0.0 0.0 0.0 -1.5707963705062866 -0.0 0.0</pose>
				<geometry>
					<mesh>
						<uri>model://model.sdf/meshes/collisions/COL__SCHUNK-5515455_G0_COL.dae</uri>
						<scale>0.00010000000623986132 0.00010000000623986132 0.00010000000623986132</scale>
					</mesh>
				</geometry>
			</collision>
			<visual name="VIS__SCHUNK-5515455_G0">
				<pose>0.0 0.0 0.0 -1.5707963705062866 -0.0 0.0</pose>
				<geometry>
					<mesh>
						<uri>model://model.sdf/meshes/visual/VIS__SCHUNK-5515455_G0.dae</uri>
						<scale>0.00010000000623986132 0.00010000000623986132 0.00010000000623986132</scale>
					</mesh>
				</geometry>
			</visual>
			<visual name="VIS__SCHUNK-9949504_A6">
				<pose>0.0 0.0 0.0 -1.5707963705062866 -0.0 0.0</pose>
				<geometry>
					<mesh>
						<uri>model://model.sdf/meshes/visual/VIS__SCHUNK-9949504_A6.dae</uri>
						<scale>0.00010000000623986132 0.00010000000623986132 0.00010000000623986132</scale>
					</mesh>
				</geometry>
			</visual>
			<visual name="VIS__SCHUNK-9905500_T7">
				<pose>0.0 0.0 0.0 -1.5707963705062866 -0.0 0.0</pose>
				<geometry>
					<mesh>
						<uri>model://model.sdf/meshes/visual/VIS__SCHUNK-9905500_T7.dae</uri>
						<scale>0.00010000000623986132 0.00010000000623986132 0.00010000000623986132</scale>
					</mesh>
				</geometry>
			</visual>
			<visual name="VIS__SCHUNK-5515457_D8">
				<pose>0.0 0.0 0.0 -1.5707963705062866 -0.0 0.0</pose>
				<geometry>
					<mesh>
						<uri>model://model.sdf/meshes/visual/VIS__SCHUNK-5515457_D8.dae</uri>
						<scale>0.00010000000623986132 0.00010000000623986132 0.00010000000623986132</scale>
					</mesh>
				</geometry>
			</visual>
			<visual name="VIS__SCHUNK-Cover_PZV1">
				<pose>0.0 0.0 0.0 -1.5707963705062866 -0.0 0.0</pose>
				<geometry>
					<mesh>
						<uri>model://model.sdf/meshes/visual/VIS__SCHUNK-Cover_PZV1.dae</uri>
						<scale>0.00010000000623986132 0.00010000000623986132 0.00010000000623986132</scale>
					</mesh>
				</geometry>
			</visual>
		</link>
		<link name="finger1">
			<pose>-0.0159999998808 0.0159999981323 0.0400000018915 1.5707963705062866 -0.0 0.0</pose>
			<inertial>
				<mass>1.0</mass>
				<pose>0 0 0 0 0 0</pose>
				<inertia>
					<ixx>1.0</ixx>
					<ixy>0.0</ixy>
					<ixz>0.0</ixz>
					<iyy>1.0</iyy>
					<iyz>0.0</iyz>
					<izz>1.0</izz>
				</inertia>
			</inertial>
			<collision name="COL_Finger1_COL">
				<pose>0.015999999880790705 -0.0400000190734866 0.016000001370906847 1.5497207073167374e-07 3.141592502593994 -1.5099580252808664e-07</pose>
				<geometry>
					<mesh>
						<uri>model://model.sdf/meshes/collisions/COL_Finger1_COL.dae</uri>
						<scale>0.00010000000623986132 0.00010000000623986132 0.00010000000623986132</scale>
					</mesh>
				</geometry>
			</collision>
			<visual name="VIS_Finger1_VIS">
				<pose>0.015999999880790705 -0.0400000190734866 0.016000001370906847 1.5497207073167374e-07 3.141592502593994 -1.5099580252808664e-07</pose>
				<geometry>
					<mesh>
						<uri>model://model.sdf/meshes/visual/VIS_Finger1_VIS.dae</uri>
						<scale>0.00010000000623986132 0.00010000000623986132 0.00010000000623986132</scale>
					</mesh>
				</geometry>
			</visual>
			<visual name="VIS__SCHUNK-5512626_f2">
				<pose>0.015999999880790705 -0.0400000190734866 0.016000001370906847 -1.5707963705062866 -0.0 0.0</pose>
				<geometry>
					<mesh>
						<uri>model://model.sdf/meshes/visual/VIS__SCHUNK-5512626_f2.dae</uri>
						<scale>0.00010000000623986132 0.00010000000623986132 0.00010000000623986132</scale>
					</mesh>
				</geometry>
			</visual>
		</link>
		<link name="finger2">
			<pose>-0.0159999998808 -0.0160000016292 0.0400000004927 1.5707963705062866 -0.0 0.0</pose>
			<inertial>
				<mass>1.0</mass>
				<pose>0 0 0 0 0 0</pose>
				<inertia>
					<ixx>1.0</ixx>
					<ixy>0.0</ixy>
					<ixz>0.0</ixz>
					<iyy>1.0</iyy>
					<iyz>0.0</iyz>
					<izz>1.0</izz>
				</inertia>
			</inertial>
			<collision name="COL_Finger2_COL">
				<pose>0.015999999880790705 -0.03999999821186062 -0.015999999880790705 -1.5099581673894136e-07 -1.5707961320877075 0.0</pose>
				<geometry>
					<mesh>
						<uri>model://model.sdf/meshes/collisions/COL_Finger2_COL.dae</uri>
						<scale>0.00010000000623986132 0.00010000000623986132 0.00010000000623986132</scale>
					</mesh>
				</geometry>
			</collision>
			<visual name="VIS_Finger2_VIS">
				<pose>0.015999999880790705 -0.03999999821186062 -0.015999999880790705 -1.5099581673894136e-07 -1.5707961320877075 0.0</pose>
				<geometry>
					<mesh>
						<uri>model://model.sdf/meshes/visual/VIS_Finger2_VIS.dae</uri>
						<scale>0.00010000000623986132 0.00010000000623986132 0.00010000000623986132</scale>
					</mesh>
				</geometry>
			</visual>
			<visual name="VIS__SCHUNK-5512626_f5">
				<pose>0.015999999880790705 -0.03999999821186062 -0.015999999880790705 -1.5707963705062866 -0.0 0.0</pose>
				<geometry>
					<mesh>
						<uri>model://model.sdf/meshes/visual/VIS__SCHUNK-5512626_f5.dae</uri>
						<scale>0.00010000000623986132 0.00010000000623986132 0.00010000000623986132</scale>
					</mesh>
				</geometry>
			</visual>
		</link>
		<link name="finger3">
			<pose>0.0159999998808 -0.0160000016292 0.0400000004927 1.5707963705062866 -0.0 0.0</pose>
			<inertial>
				<mass>1.0</mass>
				<pose>0 0 0 0 0 0</pose>
				<inertia>
					<ixx>1.0</ixx>
					<ixy>0.0</ixy>
					<ixz>0.0</ixz>
					<iyy>1.0</iyy>
					<iyz>0.0</iyz>
					<izz>1.0</izz>
				</inertia>
			</inertial>
			<collision name="COL_Finger3_COL">
				<pose>-0.015999999880790705 -0.03999999821186062 -0.015999999880790705 -3.976263318605788e-09 8.742274815176643e-08 -8.742277657347586e-08</pose>
				<geometry>
					<mesh>
						<uri>model://model.sdf/meshes/collisions/COL_Finger3_COL.dae</uri>
						<scale>0.00010000000623986132 0.00010000000623986132 0.00010000000623986132</scale>
					</mesh>
				</geometry>
			</collision>
			<visual name="VIS_Finger3_VIS">
				<pose>-0.015999999880790705 -0.03999999821186062 -0.015999999880790705 -3.976263318605788e-09 8.742274815176643e-08 -8.742277657347586e-08</pose>
				<geometry>
					<mesh>
						<uri>model://model.sdf/meshes/visual/VIS_Finger3_VIS.dae</uri>
						<scale>0.00010000000623986132 0.00010000000623986132 0.00010000000623986132</scale>
					</mesh>
				</geometry>
			</visual>
			<visual name="VIS__SCHUNK-5512626_f3">
				<pose>-0.015999999880790705 -0.03999999821186062 -0.015999999880790705 -1.5707963705062866 -0.0 0.0</pose>
				<geometry>
					<mesh>
						<uri>model://model.sdf/meshes/visual/VIS__SCHUNK-5512626_f3.dae</uri>
						<scale>0.00010000000623986132 0.00010000000623986132 0.00010000000623986132</scale>
					</mesh>
				</geometry>
			</visual>
		</link>
		<link name="finger4">
			<pose>0.0159999998808 0.0159999981323 0.0400000018915 1.5707963705062866 -0.0 0.0</pose>
			<inertial>
				<mass>1.0</mass>
				<pose>0 0 0 0 0 0</pose>
				<inertia>
					<ixx>1.0</ixx>
					<ixy>0.0</ixy>
					<ixz>0.0</ixz>
					<iyy>1.0</iyy>
					<iyz>0.0</iyz>
					<izz>1.0</izz>
				</inertia>
			</inertial>
			<collision name="COL_Finger4_COL">
				<pose>-0.015999999880790705 -0.0400000190734866 0.016000001370906847 1.5099578831723193e-07 1.5707961320877075 0.0</pose>
				<geometry>
					<mesh>
						<uri>model://model.sdf/meshes/collisions/COL_Finger4_COL.dae</uri>
						<scale>0.00010000000623986132 0.00010000000623986132 0.00010000000623986132</scale>
					</mesh>
				</geometry>
			</collision>
			<visual name="VIS_Finger4_VIS">
				<pose>-0.015999999880790705 -0.0400000190734866 0.016000001370906847 1.5099578831723193e-07 1.5707961320877075 0.0</pose>
				<geometry>
					<mesh>
						<uri>model://model.sdf/meshes/visual/VIS_Finger4_VIS.dae</uri>
						<scale>0.00010000000623986132 0.00010000000623986132 0.00010000000623986132</scale>
					</mesh>
				</geometry>
			</visual>
			<visual name="VIS__SCHUNK-5512626_f4">
				<pose>-0.015999999880790705 -0.0400000190734866 0.016000001370906847 -1.5707963705062866 -0.0 0.0</pose>
				<geometry>
					<mesh>
						<uri>model://model.sdf/meshes/visual/VIS__SCHUNK-5512626_f4.dae</uri>
						<scale>0.00010000000623986132 0.00010000000623986132 0.00010000000623986132</scale>
					</mesh>
				</geometry>
			</visual>
		</link>
		<joint name="finger1" type="prismatic">
			<parent>base</parent>
			<child>finger1</child>
			<axis>
				<xyz>1.0 0.0 0.0</xyz>
				<limit>
					<lower>-90.0</lower>
					<upper>90.0</upper>
				</limit>
			</axis>
		</joint>
		<joint name="finger2" type="prismatic">
			<parent>base</parent>
			<child>finger2</child>
			<axis>
				<xyz>0.0 0.0 1.0</xyz>
				<limit>
					<lower>-90.0</lower>
					<upper>90.0</upper>
				</limit>
			</axis>
		</joint>
		<joint name="finger3" type="prismatic">
			<parent>base</parent>
			<child>finger3</child>
			<axis>
				<xyz>0.0 0.0 1.0</xyz>
				<limit>
					<lower>-90.0</lower>
					<upper>90.0</upper>
				</limit>
			</axis>
		</joint>
		<joint name="finger4" type="prismatic">
			<parent>base</parent>
			<child>finger4</child>
			<axis>
				<xyz>0.0 0.0 1.0</xyz>
				<limit>
					<lower>-90.0</lower>
					<upper>90.0</upper>
				</limit>
			</axis>
		</joint>
	</model>
</sdf>
